<?xml version='1.0'?>

<robot name="wally" xmlns:xacro="http://www.ros.org/wiki/xacro">
  <xacro:include filename="$(find wally_description)/urdf/wally.gazebo" />

  <link name="base_link">
    <inertial>
      <origin xyz="0 0 0" rpy="0 0 0" />
      <mass value="0.380" />
      <inertia ixx="0.004708822" ixy="9.04E-07" ixz="0" iyy="0.004514873" iyz="0" izz="0.009096925" />
    </inertial>
    <visual>
      <origin xyz="0 0 0" rpy="0 0 1.57075" />
      <geometry>
	<mesh filename="package://wally_description/meshes/BASE01.dae" />
      </geometry>
    </visual>
    <collision>
      <origin xyz="0 0 0" rpy="0 0 1.57075" />
      <geometry>
	<mesh filename="package://wally_description/meshes/BASE01.dae" />
      </geometry>
    </collision>
  </link>
  <link name="Base_02">
    <inertial>
      <origin xyz="0 0 0.06" rpy="0 0 0" />
      <mass value="0.380" />
      <inertia ixx="0.004708822" ixy="9.04E-07" ixz="0" iyy="0.004514873" iyz="0" izz="0.009096925" />
    </inertial>
    <visual>
      <origin xyz="0 0 0.06" rpy="0 0 0" />
      <geometry>
	<mesh filename="package://wally_description/meshes/BASE02.dae" />
      </geometry>
    </visual>
    <collision>
      <origin xyz="0 0 0.06" rpy="0 0 0" />
      <geometry>
	<mesh filename="package://wally_description/meshes/BASE02.dae" />
      </geometry>
    </collision>
  </link>
  <joint name="base02" type="fixed">
    <origin xyz="0 0 0" rpy="0 0 1.57075" />
    <parent link="base_link" />
    <child link="Base_02" />
    <axis xyz="0 0 0" />
  </joint>
  <link name="Base_03">
    <inertial>
      <origin xyz="0 0 0.119" rpy="0 0 0" />
      <mass value="0.095" />
      <inertia ixx="0.000085867" ixy="0" ixz="0" iyy="0.000532995" iyz="0" izz="0.00061183" />
    </inertial>
    <visual>
      <origin xyz="0 0 0.119" rpy="0 0 0" />
      <geometry>
	<mesh filename="package://wally_description/meshes/BASE03.dae" />
      </geometry>
    </visual>
    <collision>
      <origin xyz="0 0 0.119" rpy="0 0 0" />
      <geometry>
	<mesh filename="package://wally_description/meshes/BASE03.dae" />
      </geometry>
    </collision>
  </link>
  <joint name="base03" type="fixed">
    <origin xyz="0 0 0" rpy="0 0 1.57075" />
    <parent link="base_link" />
    <child link="Base_03" />
    <axis xyz="0 0 0" />
  </joint>
  <link name="ZED">
    <inertial>
      <origin xyz="0 -0.08935 0.076485" rpy="0 0 0" />
      <mass value="0.135" />
      <inertia ixx="0.000021510" ixy="0" ixz="0" iyy="0.000366159" iyz="0" izz="0.000363493" />
    </inertial>
    <visual>
      <origin xyz="0 -0.08935 0.076485" rpy="0 0 0" />
      <geometry>
	<mesh filename="package://wally_description/meshes/ZED.dae" />
      </geometry>
    </visual>
    <collision>
      <origin xyz="0 -0.08935 0.076485" rpy="0 0 0" />
      <geometry>
	<mesh filename="package://wally_description/meshes/ZED.dae" />
      </geometry>
    </collision>
  </link>
  <joint name="camera" type="fixed">
    <origin xyz="0 0 0" rpy="0 0 1.57075" />
    <parent link="base_link" />
    <child link="ZED" />
    <axis xyz="0 0 0" />
  </joint>
  <link name="RP_LIDAR">
    <inertial>
      <origin xyz="0 0 0.1205" rpy="0 0 0" />
      <mass value="0.170" />
      <inertia ixx="0.000117046" ixy="-2.01E-07" ixz="-4.01E-07" iyy="0.000076301" iyz="0.000014883" izz="0.000082665" />
    </inertial>
    <visual>
      <origin xyz="0 0 0.1205" rpy="0 0 0" />
      <geometry>
	<mesh filename="package://wally_description/meshes/RP_LIDAR.dae" />
      </geometry>
    </visual>
    <collision>
      <origin xyz="0 0 0.1205" rpy="0 0 0" />
      <geometry>
	<mesh filename="package://wally_description/meshes/RP_LIDAR.dae" />
      </geometry>
    </collision>
  </link>
  <joint name="lidar" type="fixed">
    <origin xyz="0 0 0" rpy="0 0 1.57075" />
    <parent link="base_link" />
    <child link="RP_LIDAR" />
    <axis xyz="0 0 1" />
  </joint>
  <link name="motor_A">
    <inertial>
      <origin xyz="-0.11168 0 0.021875" rpy="0 0 3.1415" />
      <mass value="0.061" />
      <inertia ixx="0.000034341" ixy="0" ixz="0" iyy="0.000020393" iyz="0" izz="0.000020401" />
    </inertial>
    <visual>
      <origin xyz="-0.11168 0 0.021875" rpy="0 0 3.1415" />
      <geometry>
	<mesh filename="package://wally_description/meshes/RODA_A.dae" />
      </geometry>
    </visual>
    <collision>
      <origin xyz="-0.11168 0 0.021875" rpy="0 0 3.1415" />
      <geometry>
	<mesh filename="package://wally_description/meshes/RODA_A.dae" />
      </geometry>
    </collision>
  </link>
  <joint name="joint_A" type="continuous">
    <origin xyz="0.111681 0 -0.021875" rpy="0 0 0"/>
    <parent link="base_link" />
    <child link="motor_A" />    
    <axis xyz="0 1 0" />
  </joint>
  <link name="motor_B">
    <inertial>
      <origin xyz="-0.11168 0 -0.021875" rpy="3.1415 0 3.1415" />
      <mass value="0.061" />
      <inertia ixx="0.000034341" ixy="0" ixz="0" iyy="0.000020393" iyz="0" izz="0.000020401" />
    </inertial>
    <visual>
      <origin xyz="-0.11168 0 -0.021875" rpy="3.1415 0 3.1415" />
      <geometry>
	<mesh filename="package://wally_description/meshes/RODA_A.dae" />
      </geometry>
    </visual>
    <collision>
      <origin xyz="-0.11168 0 -0.021875" rpy="3.1415 0 3.1415" />
      <geometry>
	<mesh filename="package://wally_description/meshes/RODA_A.dae" />
      </geometry>
    </collision>
  </link>
  <joint name="joint_B" type="continuous">
    <origin xyz="0.11168 0 -0.021875" rpy="0 3.1415 0" />
    <parent link="base_link" />
    <child link="motor_B" />
    <axis xyz="0 1 0" />
  </joint>
  <link name="motor_C">
    <inertial>
      <origin xyz="0.11168 0 0.021875" rpy="0 0 0" />
      <mass value="0.061" />
      <inertia ixx="0.000034341" ixy="0" ixz="0" iyy="0.000020393" iyz="0" izz="0.000020401" />
    </inertial>
    <visual>
      <origin xyz="0.11168 0 0.021875" rpy="0 0 0" />
      <geometry>
	<mesh filename="package://wally_description/meshes/RODA_A.dae" />
      </geometry>
    </visual>
    <collision>
      <origin xyz="0.11168 0 0.021875" rpy="0 0 0" />
      <geometry>
	<mesh filename="package://wally_description/meshes/RODA_A.dae" />
      </geometry>
    </collision>
  </link>
  <joint name="joint_C" type="continuous">
    <origin xyz="-0.11168 0 -0.021875" rpy="0 0 0" />
    <parent link="base_link" />
    <child link="motor_C" />
    <axis xyz="0 1 0" />
  </joint>
  <link name="motor_D">
    <inertial>
      <origin xyz="0.11168 0 -0.021875" rpy="3.1415 0 0" />
      <mass value="0.061" />
      <inertia ixx="0.000034341" ixy="0" ixz="0" iyy="0.000020393" iyz="0" izz="0.000020401" />
    </inertial>
    <visual>
      <origin xyz="0.11168 0 -0.021875" rpy="3.1415 0 0" />
      <geometry>
	<mesh filename="package://wally_description/meshes/RODA_A.dae" />
      </geometry>
    </visual>
    <collision>
      <origin xyz="0.11168 0 -0.021875" rpy="3.1415 0 0" />
      <geometry>
	<mesh filename="package://wally_description/meshes/RODA_A.dae" />
      </geometry>
    </collision>
  </link>
  <joint name="joint_D" type="continuous">
    <origin xyz="-0.11168 0 -0.021875" rpy="0 0 0" />
    <parent link="base_link" />
    <child link="motor_D" />
    <axis xyz="0 1 0" />
  </joint>
</robot>
