<?xml	version="1.0"?>
<robot name="wally">
  <link name="base_link">
    <inertial>
      <origin xyz="-0.0083636 0.0065553 0.033694" rpy="0 0 0" />
      <mass value="1.4521" />
      <inertia ixx="0.0040255" ixy="-2.6373E-06" ixz="6.2085E-08" iyy="0.0046487" iyz="-1.1645E-06" izz="0.0086266" />
    </inertial>
    <visual>
      <origin xyz="0 0 0" rpy="0 0 0" />
      <geometry>
	<mesh filename="package://wally_description/meshes/base_link.STL" />
      </geometry>
      <material name="base">
	<color rgba="0.8 0.8 0.8 1" />
      </material>
    </visual>
    <collision>
      <origin xyz="0 0 0" rpy="0 0 0" />
      <geometry>
	<mesh filename="package://wally_description/meshes/base_link.STL" />
      </geometry>
    </collision>
  </link>
  <link name="motor_A">
    <inertial>
      <origin xyz="-4.1573E-07 -6.9339E-08 0.0137" rpy="0 0 0" />
      <mass value="0.047845" />
      <inertia ixx="1.9654E-05" ixy="9.7041E-10" ixz="-1.1174E-11" iyy="1.9654E-05" iyz="1.3746E-10" izz="3.4083E-05" />
    </inertial>
    <visual>
      <origin xyz="0 0 0" rpy="0 0 0" />
      <geometry>
	<mesh filename="package://wally_description/meshes/motor_A.STL" />
      </geometry>
      <material name="motorA">
	<color rgba="0.77647 0.55686 0.10588 1" />
      </material>
    </visual>
    <collision>
      <origin xyz="0 0 0" rpy="0 0 0" />
      <geometry>
	<mesh filename="package://wally_description/meshes/motor_A.STL" />
      </geometry>
    </collision>
  </link>
  <joint name="joint_A" type="continuous">
    <origin xyz="-0.1269 -0.11168 -0.021875" rpy="-1.5708 0.51523 1.5708" />
    <parent link="base_link" />
    <child link="motor_A" />
    <axis xyz="0 0 1" />
  </joint>
  <link name="motor_B">
    <inertial>
      <origin xyz="-4.1576E-07 -6.9176E-08 0.0137" rpy="0 0 0" />
      <mass value="0.047845" />
      <inertia ixx="1.9654E-05" ixy="9.7024E-10" ixz="-1.128E-11" iyy="1.9654E-05" iyz="1.3737E-10" izz="3.4083E-05" />
    </inertial>
    <visual>
      <origin xyz="0 0 0" rpy="0 0 0" />
      <geometry>
	<mesh filename="package://wally_description/meshes/motor_B.STL" />
      </geometry>
      <material name="motorB">
	<color rgba="0.77647 0.55686 0.10588 1" />
      </material>
    </visual>
    <collision>
      <origin xyz="0 0 0" rpy="0 0 0" />
      <geometry>
	<mesh filename="package://wally_description/meshes/motor_B.STL" />
      </geometry>
    </collision>
  </link>
  <joint name="joint_B" type="continuous">
    <origin xyz="0.1269 -0.11168 -0.021875" rpy="-1.5708 -0.57038 -1.5708" />
    <parent link="base_link" />
    <child link="motor_B" />
    <axis xyz="0 0 1" />
  </joint>
  <link name="motor_C">
    <inertial>
      <origin xyz="4.1469E-07 6.8439E-08 0.0137" rpy="0 0 0" />
      <mass value="0.047845" />
      <inertia ixx="1.9654E-05" ixy="9.7024E-10" ixz="1.0734E-11" iyy="1.9654E-05" iyz="-1.38E-10" izz="3.4083E-05" />
    </inertial>
    <visual>
      <origin xyz="0 0 0" rpy="0 0 0" />
      <geometry>
	<mesh filename="package://wally_description/meshes/motor_C.STL" />
      </geometry>
      <material name="motorC">
	<color rgba="0.77647 0.55686 0.10588 1" />
      </material>
    </visual>
    <collision>
      <origin xyz="0 0 0" rpy="0 0 0" />
      <geometry>
	<mesh filename="package://wally_description/meshes/motor_C.STL" />
      </geometry>
    </collision>
  </link>
  <joint name="joint_C" type="continuous">
    <origin xyz="0.1269 0.11168 -0.021875" rpy="1.5708 -0.50447 1.5708" />
    <parent link="base_link" />
    <child link="motor_C" />
    <axis xyz="0 0 1" />
  </joint>
  <link name="motor_D">
    <inertial>
      <origin xyz="4.1418E-07 6.8329E-08 0.0137" rpy="0 0 0" />
      <mass value="0.047845" />
      <inertia ixx="1.9654E-05" ixy="9.7033E-10" ixz="1.0826E-11" iyy="1.9654E-05" iyz="-1.3801E-10" izz="3.4083E-05" />
    </inertial>
    <visual>
      <origin xyz="0 0 0" rpy="0 0 0" />
      <geometry>
	<mesh filename="package://wally_description/meshes/motor_D.STL" />
      </geometry>
      <material name="motorD">
	<color rgba="0.77647 0.55686 0.10588 1" />
      </material>
    </visual>
    <collision>
      <origin xyz="0 0 0" rpy="0 0 0" />
      <geometry>
	<mesh filename="package://wally_description/meshes/motor_D.STL" />
      </geometry>
    </collision>
  </link>
  <joint name="joint_D" type="continuous">
    <origin xyz="-0.1269 0.11168 -0.021875" rpy="1.5708 -0.62108 -1.5708" />
    <parent link="base_link" />
    <child link="motor_D" />
    <axis xyz="0 0 1" />
  </joint>
  <link name="ZED">
    <inertial>
      <origin xyz="2.2764E-08 -2.8942E-06 0.015659" rpy="0 0 0" />
      <mass value="0.14788" />
      <inertia ixx="2.1445E-05" ixy="2.4719E-11" ixz="-1.7198E-11" iyy="0.00036611" iyz="-7.0654E-09" izz="0.00036349" />
    </inertial>
    <visual>
      <origin xyz="0 0 0" rpy="0 0 0" />
      <geometry>
	<mesh filename="package://wally_description/meshes/ZED.STL" />
      </geometry>
      <material name="">
	<color rgba="0.89804 0.91373 0.92549 1" />
      </material>
    </visual>
    <collision>
      <origin xyz="0 0 0" rpy="0 0 0" />
      <geometry>
	<mesh filename="package://wally_description/meshes/ZED.STL" />
      </geometry>
    </collision>
  </link>
  <joint name="camera" type="fixed">
    <origin xyz="0 -0.0736 0.076488" rpy="1.5708 0 0" />
    <parent link="base_link" />
    <child link="ZED" />
    <axis xyz="0 0 0" />
  </joint>
  <link name="RP_LIDAR">
    <inertial>
      <origin xyz="0 0 0" rpy="0 0 0" />
      <mass value="1e-5" />
      <inertia ixx="1e-6" ixy="0" ixz="0" iyy="1e-6" iyz="0" izz="1e-6" />
    </inertial>
    <visual>
      <origin xyz="0 0 -0.037" rpy="1.5708 0 3.14159" />
      <geometry>
	<mesh filename="package://wally_description/meshes/rp_lidarA1.stl" scale="0.01 0.01 0.01"/>
      </geometry>
      <material name="lidar">
	<color rgba="0.75294 0.75294 0.75294 1" />
      </material>
    </visual>
    <collision>
      <origin xyz="0 0 0" rpy="0 0 0" />
      <geometry>
	<mesh filename="package://wally_description/meshes/rp_lidarA1.stl" scale="0.01 0.01 0.01"/>
      </geometry>
    </collision>
  </link>
  <joint name="lidar" type="fixed">
    <origin xyz="0 0 0.158" rpy="0 0 -1.5708" />
    <parent link="base_link" />
    <child link="RP_LIDAR" />
    <axis xyz="0 1 0" />
  </joint>
</robot>
